Workbook

Sheet Basic Formulas
B1: add | C1: sub | D1: mul &div | J1: average
B2: 2 | C2: 3 | D2: =B2+C2 -> 5 | H2: 3 | I2: 4 | J2: 2 | K2: 5 | L2: =AVERAGE(H2:K2) -> 3.5
B4: 6 | C4: 4 | D4: =B4-C4 -> 2
B6: 4 | C6: 7 | D6: =B6*C6 -> 28 | L6: random number
J7: =RANDBETWEEN(1,20) -> 20 | K7: =RANDBETWEEN(1,20) -> 6 | L7: =RANDBETWEEN(1,20) -> 7 | M7: =RANDBETWEEN(1,20) -> 16 | N7: =RANDBETWEEN(1,20) -> 17 | O7: 13
B8: 6 | C8: 3 | D8: =B8/C8 -> 2 | J8: =RANDBETWEEN(1,20) -> 11 | K8: =RANDBETWEEN(1,20) -> 6 | L8: =RANDBETWEEN(1,20) -> 3 | M8: =RANDBETWEEN(1,20) -> 6 | N8: =RANDBETWEEN(1,20) -> 19 | O8: =RANDBETWEEN(1,20) -> 13 | Q8: average | R8: =AVERAGE(J7:O17) -> 10.515152
J9: =RANDBETWEEN(1,20) -> 5 | K9: =RANDBETWEEN(1,20) -> 6 | L9: =RANDBETWEEN(1,20) -> 3 | M9: =RANDBETWEEN(1,20) -> 16 | N9: =RANDBETWEEN(1,20) -> 8 | O9: =RANDBETWEEN(1,20) -> 14 | Q9: max | R9: =MAX(J7:O17) -> 20
J10: =RANDBETWEEN(1,20) -> 1 | K10: =RANDBETWEEN(1,20) -> 12 | L10: =RANDBETWEEN(1,20) -> 18 | M10: =RANDBETWEEN(1,20) -> 8 | N10: =RANDBETWEEN(1,20) -> 5 | O10: =RANDBETWEEN(1,20) -> 6 | Q10: min | R10: =MIN(J7:O17) -> 1
J11: =RANDBETWEEN(1,20) -> 6 | K11: =RANDBETWEEN(1,20) -> 12 | L11: =RANDBETWEEN(1,20) -> 20 | M11: =RANDBETWEEN(1,20) -> 9 | N11: =RANDBETWEEN(1,20) -> 19 | O11: =RANDBETWEEN(1,20) -> 19 | Q11: count | R11: =COUNT(J7:O17) -> 66
J12: =RANDBETWEEN(1,20) -> 20 | K12: =RANDBETWEEN(1,20) -> 4 | L12: =RANDBETWEEN(1,20) -> 5 | M12: =RANDBETWEEN(1,20) -> 6 | N12: =RANDBETWEEN(1,20) -> 17 | O12: =RANDBETWEEN(1,20) -> 2
J13: =RANDBETWEEN(1,20) -> 1 | K13: =RANDBETWEEN(1,20) -> 3 | L13: =RANDBETWEEN(1,20) -> 11 | M13: =RANDBETWEEN(1,20) -> 10 | N13: =RANDBETWEEN(1,20) -> 19 | O13: =RANDBETWEEN(1,20) -> 10
J14: =RANDBETWEEN(1,20) -> 17 | K14: =RANDBETWEEN(1,20) -> 18 | L14: =RANDBETWEEN(1,20) -> 11 | M14: =RANDBETWEEN(1,20) -> 19 | N14: =RANDBETWEEN(1,20) -> 9 | O14: =RANDBETWEEN(1,20) -> 13
J15: =RANDBETWEEN(1,20) -> 20 | K15: =RANDBETWEEN(1,20) -> 3 | L15: =RANDBETWEEN(1,20) -> 3 | M15: =RANDBETWEEN(1,20) -> 6 | N15: =RANDBETWEEN(1,20) -> 18 | O15: =RANDBETWEEN(1,20) -> 9
J16: =RANDBETWEEN(1,20) -> 14 | K16: =RANDBETWEEN(1,20) -> 6 | L16: =RANDBETWEEN(1,20) -> 18 | M16: =RANDBETWEEN(1,20) -> 2 | N16: =RANDBETWEEN(1,20) -> 13 | O16: =RANDBETWEEN(1,20) -> 13
J17: =RANDBETWEEN(1,20) -> 8 | K17: =RANDBETWEEN(1,20) -> 6 | L17: =RANDBETWEEN(1,20) -> 5 | M17: =RANDBETWEEN(1,20) -> 8 | N17: =RANDBETWEEN(1,20) -> 15 | O17: =RANDBETWEEN(1,20) -> 8
L19: vlookup
K20: serial number | L20: family | M20: income
B21: if | F21: database | K21: 1 | L21: fa1 | M21: 13
B22: if-or | E22: person | F22: income | K22: 2 | L22: fa2 | M22: 10
B23: if-error | E23: 1 | F23: =RANDBETWEEN(10000,25000) -> 15297 | G23: if | H23: =IF(F23>F24,"yes","no") -> no | K23: 3 | L23: fa3 | M23: 20
B24: vlookup | E24: 2 | F24: =RANDBETWEEN(10000,25000) -> 18181 | G24: if-or | H24: =IF(OR(F23>F24>F25>F26>F27),"yes","no") -> yes | K24: 4 | L24: fa4 | M24: 15
E25: 3 | F25: =RANDBETWEEN(10000,25000) -> 17300 | K25: vlookup formula
E26: 4 | F26: =RANDBETWEEN(10000,25000) -> 22858 | K26: search number | L26: fam name
E27: 5 | F27: =RANDBETWEEN(10000,25000) -> 19622 | K27: 3 | L27: =VLOOKUP(K27,K20:M24,3) -> 20
E30: 5 | F30: a | G30: if-error | H30: =IFERROR(E30*F30,"error") -> error

Sheet Employee
A1: Employee ID | B1: Name | C1: Department | D1: Joining Date | E1: Salary | F1: Performance score | H1: BASIC AGREGGATION
A2: E5 | B2: Robin | C2: =CHOOSE(RANDBETWEEN(1,9), "HR","Sales","Finance","Data Analyst","IT Support","Data Science","Accounting","Marketing","Customer") -> Customer | D2: =RANDBETWEEN(DATE(2023,20,4), DATE(2025,12,31)) -> 45637 | E2: =RANDBETWEEN(40000,100000) -> 97694 | F2: =RANDBETWEEN(60,90) -> 90 | H2: Total Employees | I2: Total payroll | J2: Average Salary | K2: Min Salary | L2: Max Salary | M2: Average performance | N2: count of it support | O2: Average salary of HR dept
A3: E35 | B3: Noah | C3: =CHOOSE(RANDBETWEEN(1,9), "HR","Sales","Finance","Data Analyst","IT Support","Data Science","Accounting","Marketing","Customer") -> Sales | D3: =RANDBETWEEN(DATE(2023,20,4), DATE(2025,12,31)) -> 45897 | E3: =RANDBETWEEN(40000,100000) -> 76794 | F3: =RANDBETWEEN(60,90) -> 67 | H3: =COUNTA(A2:A53) -> 50 | I3: =SUM(E2:E51) -> 3618376 | J3: =AVERAGE(E2:E51) -> 72367.52 | K3: =MIN(E2:E51) -> 40705 | L3: =MAX(E2:E51) -> 99594 | M3: =AVERAGE(F2:F51) -> 74.08 | N3: =COUNTIF(C2:C51,"IT Support") -> 4 | O3: =AVERAGEIF(C2:C100,"HR",E2:E100) -> 78198.6
A4: E13 | B4: Lucas | C4: =CHOOSE(RANDBETWEEN(1,9), "HR","Sales","Finance","Data Analyst","IT Support","Data Science","Accounting","Marketing","Customer") -> Sales | D4: =RANDBETWEEN(DATE(2023,20,4), DATE(2025,12,31)) -> 45695 | E4: =RANDBETWEEN(40000,100000) -> 41810 | F4: =RANDBETWEEN(60,90) -> 73
A5: E12 | B5: Erica | C5: =CHOOSE(RANDBETWEEN(1,9), "HR","Sales","Finance","Data Analyst","IT Support","Data Science","Accounting","Marketing","Customer") -> Marketing | D5: =RANDBETWEEN(DATE(2023,20,4), DATE(2025,12,31)) -> 45993 | E5: =RANDBETWEEN(40000,100000) -> 86325 | F5: =RANDBETWEEN(60,90) -> 69
A6: E33 | B6: Isabell | C6: =CHOOSE(RANDBETWEEN(1,9), "HR","Sales","Finance","Data Analyst","IT Support","Data Science","Accounting","Marketing","Customer") -> Finance | D6: =RANDBETWEEN(DATE(2023,20,4), DATE(2025,12,31)) -> 45606 | E6: =RANDBETWEEN(40000,100000) -> 52391 | F6: =RANDBETWEEN(60,90) -> 72 | J6: DATE BASED FORMULA | L6: CONDITIONAL FORMATING
A7: E11 | B7: Murray | C7: =CHOOSE(RANDBETWEEN(1,9), "HR","Sales","Finance","Data Analyst","IT Support","Data Science","Accounting","Marketing","Customer") -> Data Science | D7: =RANDBETWEEN(DATE(2023,20,4), DATE(2025,12,31)) -> 45741 | E7: =RANDBETWEEN(40000,100000) -> 44778 | F7: =RANDBETWEEN(60,90) -> 67 | J7: years of experience | L7: Label high salary (>50000)
A8: E15 | B8: Maxine | C8: =CHOOSE(RANDBETWEEN(1,9), "HR","Sales","Finance","Data Analyst","IT Support","Data Science","Accounting","Marketing","Customer") -> IT Support | D8: =RANDBETWEEN(DATE(2023,20,4), DATE(2025,12,31)) -> 45664 | E8: =RANDBETWEEN(40000,100000) -> 83695 | F8: =RANDBETWEEN(60,90) -> 63 | J8: {=DATEDIF(D2:D51,TODAY(),"Y")} -> 0 | L8: =IF(E2>50000,"High","Normal") -> High
A9: E7 | B9: Jonathon | C9: =CHOOSE(RANDBETWEEN(1,9), "HR","Sales","Finance","Data Analyst","IT Support","Data Science","Accounting","Marketing","Customer") -> Sales | D9: =RANDBETWEEN(DATE(2023,20,4), DATE(2025,12,31)) -> 45632 | E9: =RANDBETWEEN(40000,100000) -> 79645 | F9: =RANDBETWEEN(60,90) -> 78 | J9: 0 | L9: =IF(E3>50000,"High","Normal") -> High
A10: E29 | B10: Stefan | C10: =CHOOSE(RANDBETWEEN(1,9), "HR","Sales","Finance","Data Analyst","IT Support","Data Science","Accounting","Marketing","Customer") -> Finance | D10: =RANDBETWEEN(DATE(2023,20,4), DATE(2025,12,31)) -> 45994 | E10: =RANDBETWEEN(40000,100000) -> 53903 | F10: =RANDBETWEEN(60,90) -> 76 | J10: 0 | L10: =IF(E4>50000,"High","Normal") -> Normal
A11: E17 | B11: Karren | C11: =CHOOSE(RANDBETWEEN(1,9), "HR","Sales","Finance","Data Analyst","IT Support","Data Science","Accounting","Marketing","Customer") -> Finance | D11: =RANDBETWEEN(DATE(2023,20,4), DATE(2025,12,31)) -> 45651 | E11: =RANDBETWEEN(40000,100000) -> 46917 | F11: =RANDBETWEEN(60,90) -> 71 | J11: #NUM! | L11: =IF(E5>50000,"High","Normal") -> High
A12: E24 | B12: Lucy | C12: =CHOOSE(RANDBETWEEN(1,9), "HR","Sales","Finance","Data Analyst","IT Support","Data Science","Accounting","Marketing","Customer") -> Finance | D12: =RANDBETWEEN(DATE(2023,20,4), DATE(2025,12,31)) -> 45783 | E12: =RANDBETWEEN(40000,100000) -> 55028 | F12: =RANDBETWEEN(60,90) -> 89 | J12: 1 | L12: =IF(E6>50000,"High","Normal") -> High
A13: E42 | B13: Emma | C13: =CHOOSE(RANDBETWEEN(1,9), "HR","Sales","Finance","Data Analyst","IT Support","Data Science","Accounting","Marketing","Customer") -> IT Support | D13: =RANDBETWEEN(DATE(2023,20,4), DATE(2025,12,31)) -> 45987 | E13: =RANDBETWEEN(40000,100000) -> 87859 | F13: =RANDBETWEEN(60,90) -> 83 | J13: 0 | L13: =IF(E7>50000,"High","Normal") -> Normal
A14: E14 | B14: Dustin | C14: =CHOOSE(RANDBETWEEN(1,9), "HR","Sales","Finance","Data Analyst","IT Support","Data Science","Accounting","Marketing","Customer") -> Accounting | D14: =RANDBETWEEN(DATE(2023,20,4), DATE(2025,12,31)) -> 45646 | E14: =RANDBETWEEN(40000,100000) -> 92391 | F14: =RANDBETWEEN(60,90) -> 89 | J14: 0 | L14: =IF(E8>50000,"High","Normal") -> High
A15: E22 | B15: Molly | C15: =CHOOSE(RANDBETWEEN(1,9), "HR","Sales","Finance","Data Analyst","IT Support","Data Science","Accounting","Marketing","Customer") -> Customer | D15: =RANDBETWEEN(DATE(2023,20,4), DATE(2025,12,31)) -> 45533 | E15: =RANDBETWEEN(40000,100000) -> 93180 | F15: =RANDBETWEEN(60,90) -> 60 | J15: 0 | L15: =IF(E9>50000,"High","Normal") -> High
A16: E47 | B16: Sadie | C16: =CHOOSE(RANDBETWEEN(1,9), "HR","Sales","Finance","Data Analyst","IT Support","Data Science","Accounting","Marketing","Customer") -> IT Support | D16: =RANDBETWEEN(DATE(2023,20,4), DATE(2025,12,31)) -> 45711 | E16: =RANDBETWEEN(40000,100000) -> 89009 | F16: =RANDBETWEEN(60,90) -> 86 | J16: #NUM! | L16: =IF(E10>50000,"High","Normal") -> High
A17: E43 | B17: Olivia | C17: =CHOOSE(RANDBETWEEN(1,9), "HR","Sales","Finance","Data Analyst","IT Support","Data Science","Accounting","Marketing","Customer") -> Data Analyst | D17: =RANDBETWEEN(DATE(2023,20,4), DATE(2025,12,31)) -> 45526 | E17: =RANDBETWEEN(40000,100000) -> 64807 | F17: =RANDBETWEEN(60,90) -> 76 | J17: 0 | L17: =IF(E11>50000,"High","Normal") -> Normal
A18: E20 | B18: Eddie | C18: =CHOOSE(RANDBETWEEN(1,9), "HR","Sales","Finance","Data Analyst","IT Support","Data Science","Accounting","Marketing","Customer") -> Sales | D18: =RANDBETWEEN(DATE(2023,20,4), DATE(2025,12,31)) -> 45816 | E18: =RANDBETWEEN(40000,100000) -> 56894 | F18: =RANDBETWEEN(60,90) -> 75 | J18: 0 | L18: =IF(E12>50000,"High","Normal") -> High
A19: E41 | B19: Liam | C19: =CHOOSE(RANDBETWEEN(1,9), "HR","Sales","Finance","Data Analyst","IT Support","Data Science","Accounting","Marketing","Customer") -> Data Analyst | D19: =RANDBETWEEN(DATE(2023,20,4), DATE(2025,12,31)) -> 45841 | E19: =RANDBETWEEN(40000,100000) -> 90951 | F19: =RANDBETWEEN(60,90) -> 83 | J19: 0 | L19: =IF(E13>50000,"High","Normal") -> High
A20: E30 | B20: Klaus | C20: =CHOOSE(RANDBETWEEN(1,9), "HR","Sales","Finance","Data Analyst","IT Support","Data Science","Accounting","Marketing","Customer") -> HR | D20: =RANDBETWEEN(DATE(2023,20,4), DATE(2025,12,31)) -> 45754 | E20: =RANDBETWEEN(40000,100000) -> 41847 | F20: =RANDBETWEEN(60,90) -> 78 | J20: 0 | L20: =IF(E14>50000,"High","Normal") -> High
A21: E44 | B21: Sophia | C21: =CHOOSE(RANDBETWEEN(1,9), "HR","Sales","Finance","Data Analyst","IT Support","Data Science","Accounting","Marketing","Customer") -> Data Analyst | D21: =RANDBETWEEN(DATE(2023,20,4), DATE(2025,12,31)) -> 45854 | E21: =RANDBETWEEN(40000,100000) -> 40705 | F21: =RANDBETWEEN(60,90) -> 86 | J21: 1 | L21: =IF(E15>50000,"High","Normal") -> High
A22: E16 | B22: Sussy | C22: =CHOOSE(RANDBETWEEN(1,9), "HR","Sales","Finance","Data Analyst","IT Support","Data Science","Accounting","Marketing","Customer") -> Finance | D22: =RANDBETWEEN(DATE(2023,20,4), DATE(2025,12,31)) -> 45564 | E22: =RANDBETWEEN(40000,100000) -> 86330 | F22: =RANDBETWEEN(60,90) -> 66 | J22: 0 | L22: =IF(E16>50000,"High","Normal") -> High
A23: E48 | B23: Chole | C23: =CHOOSE(RANDBETWEEN(1,9), "HR","Sales","Finance","Data Analyst","IT Support","Data Science","Accounting","Marketing","Customer") -> Customer | D23: =RANDBETWEEN(DATE(2023,20,4), DATE(2025,12,31)) -> 45800 | E23: =RANDBETWEEN(40000,100000) -> 73085 | F23: =RANDBETWEEN(60,90) -> 64 | J23: 1 | L23: =IF(E17>50000,"High","Normal") -> High
A24: E32 | B24: Jermaiah | C24: =CHOOSE(RANDBETWEEN(1,9), "HR","Sales","Finance","Data Analyst","IT Support","Data Science","Accounting","Marketing","Customer") -> Finance | D24: =RANDBETWEEN(DATE(2023,20,4), DATE(2025,12,31)) -> 45754 | E24: =RANDBETWEEN(40000,100000) -> 42798 | F24: =RANDBETWEEN(60,90) -> 87 | J24: 0 | L24: =IF(E18>50000,"High","Normal") -> High
A25: E31 | B25: Rossaline | C25: =CHOOSE(RANDBETWEEN(1,9), "HR","Sales","Finance","Data Analyst","IT Support","Data Science","Accounting","Marketing","Customer") -> Data Analyst | D25: =RANDBETWEEN(DATE(2023,20,4), DATE(2025,12,31)) -> 45521 | E25: =RANDBETWEEN(40000,100000) -> 80591 | F25: =RANDBETWEEN(60,90) -> 90 | J25: 0 | L25: =IF(E19>50000,"High","Normal") -> High
A26: E6 | B26: Nancy | C26: =CHOOSE(RANDBETWEEN(1,9), "HR","Sales","Finance","Data Analyst","IT Support","Data Science","Accounting","Marketing","Customer") -> HR | D26: =RANDBETWEEN(DATE(2023,20,4), DATE(2025,12,31)) -> 45809 | E26: =RANDBETWEEN(40000,100000) -> 90196 | F26: =RANDBETWEEN(60,90) -> 74 | J26: 0 | L26: =IF(E20>50000,"High","Normal") -> Normal
A27: E19 | B27: Billy | C27: =CHOOSE(RANDBETWEEN(1,9), "HR","Sales","Finance","Data Analyst","IT Support","Data Science","Accounting","Marketing","Customer") -> Finance | D27: =RANDBETWEEN(DATE(2023,20,4), DATE(2025,12,31)) -> 45880 | E27: =RANDBETWEEN(40000,100000) -> 48779 | F27: =RANDBETWEEN(60,90) -> 88 | J27: 0 | L27: =IF(E21>50000,"High","Normal") -> Normal
A28: E10 | B28: Gim | C28: =CHOOSE(RANDBETWEEN(1,9), "HR","Sales","Finance","Data Analyst","IT Support","Data Science","Accounting","Marketing","Customer") -> Data Science | D28: =RANDBETWEEN(DATE(2023,20,4), DATE(2025,12,31)) -> 45554 | E28: =RANDBETWEEN(40000,100000) -> 61653 | F28: =RANDBETWEEN(60,90) -> 62 | J28: 1 | L28: =IF(E22>50000,"High","Normal") -> High
... A42: E4 | B42: Steve | C42: =CHOOSE(RANDBETWEEN(1,9), "HR","Sales","Finance","Data Analyst","IT Support","Data Science","Accounting","Marketing","Customer") -> Data Science | D42: =RANDBETWEEN(DATE(2023,20,4), DATE(2025,12,31)) -> 45791 | E42: =RANDBETWEEN(40000,100000) -> 49660 | F42: =RANDBETWEEN(60,90) -> 64 | J42: 1 | L42: =IF(E36>50000,"High","Normal") -> High
A43: E9 | B43: Joyce | C43: =CHOOSE(RANDBETWEEN(1,9), "HR","Sales","Finance","Data Analyst","IT Support","Data Science","Accounting","Marketing","Customer") -> Customer | D43: =RANDBETWEEN(DATE(2023,20,4), DATE(2025,12,31)) -> 45896 | E43: =RANDBETWEEN(40000,100000) -> 66855 | F43: =RANDBETWEEN(60,90) -> 66 | J43: #NUM! | L43: =IF(E37>50000,"High","Normal") -> High
A44: E39 | B44: Elijah | C44: =CHOOSE(RANDBETWEEN(1,9), "HR","Sales","Finance","Data Analyst","IT Support","Data Science","Accounting","Marketing","Customer") -> Data Science | D44: =RANDBETWEEN(DATE(2023,20,4), DATE(2025,12,31)) -> 45982 | E44: =RANDBETWEEN(40000,100000) -> 76001 | F44: =RANDBETWEEN(60,90) -> 60 | J44: 1 | L44: =IF(E38>50000,"High","Normal") -> High
A45: E28 | B45: Caroline | C45: =CHOOSE(RANDBETWEEN(1,9), "HR","Sales","Finance","Data Analyst","IT Support","Data Science","Accounting","Marketing","Customer") -> Finance | D45: =RANDBETWEEN(DATE(2023,20,4), DATE(2025,12,31)) -> 45899 | E45: =RANDBETWEEN(40000,100000) -> 90393 | F45: =RANDBETWEEN(60,90) -> 67 | J45: 0 | L45: =IF(E39>50000,"High","Normal") -> High
A46: E40 | B46: James | C46: =CHOOSE(RANDBETWEEN(1,9), "HR","Sales","Finance","Data Analyst","IT Support","Data Science","Accounting","Marketing","Customer") -> Data Science | D46: =RANDBETWEEN(DATE(2023,20,4), DATE(2025,12,31)) -> 45978 | E46: =RANDBETWEEN(40000,100000) -> 86390 | F46: =RANDBETWEEN(60,90) -> 68 | J46: 0 | L46: =IF(E40>50000,"High","Normal") -> High
A47: E37 | B47: Finn | C47: =CHOOSE(RANDBETWEEN(1,9), "HR","Sales","Finance","Data Analyst","IT Support","Data Science","Accounting","Marketing","Customer") -> Customer | D47: =RANDBETWEEN(DATE(2023,20,4), DATE(2025,12,31)) -> 45918 | E47: =RANDBETWEEN(40000,100000) -> 83398 | F47: =RANDBETWEEN(60,90) -> 82 | J47: 0 | L47: =IF(E41>50000,"High","Normal") -> High
A48: E18 | B48: Ben | C48: =CHOOSE(RANDBETWEEN(1,9), "HR","Sales","Finance","Data Analyst","IT Support","Data Science","Accounting","Marketing","Customer") -> HR | D48: =RANDBETWEEN(DATE(2023,20,4), DATE(2025,12,31)) -> 45605 | E48: =RANDBETWEEN(40000,100000) -> 94271 | F48: =RANDBETWEEN(60,90) -> 72 | J48: 0 | L48: =IF(E42>50000,"High","Normal") -> Normal
A49: E45 | B49: Luna | C49: =CHOOSE(RANDBETWEEN(1,9), "HR","Sales","Finance","Data Analyst","IT Support","Data Science","Accounting","Marketing","Customer") -> Accounting | D49: =RANDBETWEEN(DATE(2023,20,4), DATE(2025,12,31)) -> 46018 | E49: =RANDBETWEEN(40000,100000) -> 63126 | F49: =RANDBETWEEN(60,90) -> 67 | J49: 0 | L49: =IF(E43>50000,"High","Normal") -> High
A50: E3 | B50: William | C50: =CHOOSE(RANDBETWEEN(1,9), "HR","Sales","Finance","Data Analyst","IT Support","Data Science","Accounting","Marketing","Customer") -> Accounting | D50: =RANDBETWEEN(DATE(2023,20,4), DATE(2025,12,31)) -> 46019 | E50: =RANDBETWEEN(40000,100000) -> 85299 | F50: =RANDBETWEEN(60,90) -> 74 | J50: 0 | L50: =IF(E44>50000,"High","Normal") -> High
A51: E1 | B51: Jane | C51: =CHOOSE(RANDBETWEEN(1,9), "HR","Sales","Finance","Data Analyst","IT Support","Data Science","Accounting","Marketing","Customer") -> Marketing | D51: =RANDBETWEEN(DATE(2023,20,4), DATE(2025,12,31)) -> 45804 | E51: =RANDBETWEEN(40000,100000) -> 66111 | F51: =RANDBETWEEN(60,90) -> 67 | J51: 0 | L51: =IF(E45>50000,"High","Normal") -> High
J52: 0 | L52: =IF(E46>50000,"High","Normal") -> High
J53: 0 | L53: =IF(E47>50000,"High","Normal") -> High
...

Sheet Product
A1: Product ID | B1: Product Name | C1: Category | D1: Price | H1: product name | I1: category | J1: AGGREGATIONS | O1: CONDITIONAL
A2: P4 | B2: {=INDEX($H$2:$H$11, RANDBETWEEN(1,10))} -> bluetooth speaker | C2: =VLOOKUP(B2, $H$2:$I$11, 2, FALSE) -> electronics | D2: =RANDBETWEEN(500,1000) -> 590 | H2: Refrigerator | I2: Home applicance | J2: Total products | K2: Sum of all product prices | L2: Highest price | M2: Lowest price | O2: Identify expensive products (>1000) | P2: Count products in "Electronics"
A3: P16 | B3: {=INDEX($H$2:$H$11, RANDBETWEEN(1,10))} -> tshirt | C3: =VLOOKUP(B3, $H$2:$I$11, 2, FALSE) -> fashion | D3: =RANDBETWEEN(500,1000) -> 600 | H3: shampoo | I3: Beauty | J3: =COUNTA(A2:A51) -> 50 | K3: =SUM(D2:D51) -> 38240 | L3: =MAX(D2:D51) -> 999 | M3: =MIN(D2:D51) -> 510 | O3: =IF(D2>1000,"Expensive","Affordable") -> Affordable | P3: =COUNTIF(C2:C51,"Electronics") -> 1
A4: P31 | B4: {=INDEX($H$2:$H$11, RANDBETWEEN(1,10))} -> Refrigerator | C4: =VLOOKUP(B4, $H$2:$I$11, 2, FALSE) -> Home applicance | D4: =RANDBETWEEN(500,1000) -> 951 | H4: rice bag | I4: grocery
A5: P43 | B5: {=INDEX($H$2:$H$11, RANDBETWEEN(1,10))} -> rice bag | C5: =VLOOKUP(B5, $H$2:$I$11, 2, FALSE) -> grocery | D5: =RANDBETWEEN(500,1000) -> 566 | H5: bluetooth speaker | I5: electronics
A6: P24 | B6: {=INDEX($H$2:$H$11, RANDBETWEEN(1,10))} -> tshirt | C6: =VLOOKUP(B6, $H$2:$I$11, 2, FALSE) -> fashion | D6: =RANDBETWEEN(500,1000) -> 692 | H6: smart phone | I6: mobile
A7: P29 | B7: {=INDEX($H$2:$H$11, RANDBETWEEN(1,10))} -> shampoo | C7: =VLOOKUP(B7, $H$2:$I$11, 2, FALSE) -> Beauty | D7: =RANDBETWEEN(500,1000) -> 781 | H7: tshirt | I7: fashion
A8: P32 | B8: {=INDEX($H$2:$H$11, RANDBETWEEN(1,10))} -> shampoo | C8: =VLOOKUP(B8, $H$2:$I$11, 2, FALSE) -> Beauty | D8: =RANDBETWEEN(500,1000) -> 759 | H8: notebook | I8: stationary
A9: P8 | B9: {=INDEX($H$2:$H$11, RANDBETWEEN(1,10))} -> vitamins | C9: =VLOOKUP(B9, $H$2:$I$11, 2, FALSE) -> health | D9: =RANDBETWEEN(500,1000) -> 580 | H9: story book | I9: book
A10: P14 | B10: {=INDEX($H$2:$H$11, RANDBETWEEN(1,10))} -> smart phone | C10: =VLOOKUP(B10, $H$2:$I$11, 2, FALSE) -> mobile | D10: =RANDBETWEEN(500,1000) -> 573 | H10: teddy bear | I10: toys
A11: P34 | B11: {=INDEX($H$2:$H$11, RANDBETWEEN(1,10))} -> notebook | C11: =VLOOKUP(B11, $H$2:$I$11, 2, FALSE) -> stationary | D11: =RANDBETWEEN(500,1000) -> 961 | H11: vitamins | I11: health
A12: P6 | B12: {=INDEX($H$2:$H$11, RANDBETWEEN(1,10))} -> smart phone | C12: =VLOOKUP(B12, $H$2:$I$11, 2, FALSE) -> mobile | D12: =RANDBETWEEN(500,1000) -> 610
A13: P12 | B13: {=INDEX($H$2:$H$11, RANDBETWEEN(1,10))} -> teddy bear | C13: =VLOOKUP(B13, $H$2:$I$11, 2, FALSE) -> toys | D13: =RANDBETWEEN(500,1000) -> 796
A14: P35 | B14: {=INDEX($H$2:$H$11, RANDBETWEEN(1,10))} -> shampoo | C14: =VLOOKUP(B14, $H$2:$I$11, 2, FALSE) -> Beauty | D14: =RANDBETWEEN(500,1000) -> 777
A15: P46 | B15: {=INDEX($H$2:$H$11, RANDBETWEEN(1,10))} -> teddy bear | C15: =VLOOKUP(B15, $H$2:$I$11, 2, FALSE) -> toys | D15: =RANDBETWEEN(500,1000) -> 515
A16: P47 | B16: {=INDEX($H$2:$H$11, RANDBETWEEN(1,10))} -> rice bag | C16: =VLOOKUP(B16, $H$2:$I$11, 2, FALSE) -> grocery | D16: =RANDBETWEEN(500,1000) -> 985
A17: P50 | B17: {=INDEX($H$2:$H$11, RANDBETWEEN(1,10))} -> teddy bear | C17: =VLOOKUP(B17, $H$2:$I$11, 2, FALSE) -> toys | D17: =RANDBETWEEN(500,1000) -> 514
A18: P3 | B18: {=INDEX($H$2:$H$11, RANDBETWEEN(1,10))} -> teddy bear | C18: =VLOOKUP(B18, $H$2:$I$11, 2, FALSE) -> toys | D18: =RANDBETWEEN(500,1000) -> 734
A19: P27 | B19: {=INDEX($H$2:$H$11, RANDBETWEEN(1,10))} -> Refrigerator | C19: =VLOOKUP(B19, $H$2:$I$11, 2, FALSE) -> Home applicance | D19: =RANDBETWEEN(500,1000) -> 971
A20: P38 | B20: {=INDEX($H$2:$H$11, RANDBETWEEN(1,10))} -> teddy bear | C20: =VLOOKUP(B20, $H$2:$I$11, 2, FALSE) -> toys | D20: =RANDBETWEEN(500,1000) -> 988
A21: P45 | B21: {=INDEX($H$2:$H$11, RANDBETWEEN(1,10))} -> Refrigerator | C21: =VLOOKUP(B21, $H$2:$I$11, 2, FALSE) -> Home applicance | D21: =RANDBETWEEN(500,1000) -> 850
A22: P5 | B22: {=INDEX($H$2:$H$11, RANDBETWEEN(1,10))} -> shampoo | C22: =VLOOKUP(B22, $H$2:$I$11, 2, FALSE) -> Beauty | D22: =RANDBETWEEN(500,1000) -> 933
A23: P13 | B23: {=INDEX($H$2:$H$11, RANDBETWEEN(1,10))} -> story book | C23: =VLOOKUP(B23, $H$2:$I$11, 2, FALSE) -> book | D23: =RANDBETWEEN(500,1000) -> 881
... A51: P49 | B51: {=INDEX($H$2:$H$11, RANDBETWEEN(1,10))} -> notebook | C51: =VLOOKUP(B51, $H$2:$I$11, 2, FALSE) -> stationary | D51: =RANDBETWEEN(500,1000) -> 999

Sheet Sales
A1: Sales ID | B1: Employee ID | C1: Product ID | D1: Units Sold | E1: Sale Date | F1: Sale Amount | I1: AGGREGATE FUNCTIONS | N1: CONDITIONAL
A2: S27 | B2: E27 | C2: P27 | D2: =RANDBETWEEN(1,3) -> 3 | E2: =RANDBETWEEN(DATE(2024,1,1), DATE(2024,12,31)) -> 45627 | F2: =D2 * VLOOKUP(C2, Product!$A$2:$D$51, 4, FALSE) -> 2913 | I2: sales amt | J2: units sold sum | K2: max sale amt | L2: min sale amt | N2: Flag high sales (>10,000) | O2: Check weekend sales
A3: S2 | B3: E2 | C3: P2 | D3: =RANDBETWEEN(1,3) -> 1 | E3: =RANDBETWEEN(DATE(2024,1,1), DATE(2024,12,31)) -> 45364 | F3: =D3 * VLOOKUP(C3, Product!$A$2:$D$51, 4, FALSE) -> 662 | I3: =SUM(F2:F51) -> 76169 | J3: =SUM(D2:D51) -> 100 | K3: =MAX(F2:F51) -> 2988 | L3: =MIN(F2:F51) -> 573 | N3: =IF(F2>10000,"High","Low") -> Low | O3: =IF(WEEKDAY(E2)=1,"Sunday Sale", IF(WEEKDAY(E2)=7,"Saturday Sale","Weekday Sale")) -> Sunday Sale
A4: S42 | B4: E42 | C4: P42 | D4: =RANDBETWEEN(1,3) -> 2 | E4: =RANDBETWEEN(DATE(2024,1,1), DATE(2024,12,31)) -> 45508 | F4: =D4 * VLOOKUP(C4, Product!$A$2:$D$51, 4, FALSE) -> 1506
A5: S21 | B5: E21 | C5: P21 | D5: =RANDBETWEEN(1,3) -> 1 | E5: =RANDBETWEEN(DATE(2024,1,1), DATE(2024,12,31)) -> 45490 | F5: =D5 * VLOOKUP(C5, Product!$A$2:$D$51, 4, FALSE) -> 602
A6: S33 | B6: E33 | C6: P33 | D6: =RANDBETWEEN(1,3) -> 1 | E6: =RANDBETWEEN(DATE(2024,1,1), DATE(2024,12,31)) -> 45449 | F6: =D6 * VLOOKUP(C6, Product!$A$2:$D$51, 4, FALSE) -> 875
A7: S3 | B7: E3 | C7: P3 | D7: =RANDBETWEEN(1,3) -> 1 | E7: =RANDBETWEEN(DATE(2024,1,1), DATE(2024,12,31)) -> 45657 | F7: =D7 * VLOOKUP(C7, Product!$A$2:$D$51, 4, FALSE) -> 734
A8: S12 | B8: E12 | C8: P12 | D8: =RANDBETWEEN(1,3) -> 3 | E8: =RANDBETWEEN(DATE(2024,1,1), DATE(2024,12,31)) -> 45429 | F8: =D8 * VLOOKUP(C8, Product!$A$2:$D$51, 4, FALSE) -> 2388
A9: S45 | B9: E45 | C9: P45 | D9: =RANDBETWEEN(1,3) -> 2 | E9: =RANDBETWEEN(DATE(2024,1,1), DATE(2024,12,31)) -> 45635 | F9: =D9 * VLOOKUP(C9, Product!$A$2:$D$51, 4, FALSE) -> 1700
A10: S40 | B10: E40 | C10: P40 | D10: =RANDBETWEEN(1,3) -> 1 | E10: =RANDBETWEEN(DATE(2024,1,1), DATE(2024,12,31)) -> 45379 | F10: =D10 * VLOOKUP(C10, Product!$A$2:$D$51, 4, FALSE) -> 651
A11: S8 | B11: E8 | C11: P8 | D11: =RANDBETWEEN(1,3) -> 1 | E11: =RANDBETWEEN(DATE(2024,1,1), DATE(2024,12,31)) -> 45332 | F11: =D11 * VLOOKUP(C11, Product!$A$2:$D$51, 4, FALSE) -> 580
A12: S9 | B12: E9 | C12: P9 | D12: =RANDBETWEEN(1,3) -> 2 | E12: =RANDBETWEEN(DATE(2024,1,1), DATE(2024,12,31)) -> 45414 | F12: =D12 * VLOOKUP(C12, Product!$A$2:$D$51, 4, FALSE) -> 1248
A13: S48 | B13: E48 | C13: P48 | D13: =RANDBETWEEN(1,3) -> 3 | E13: =RANDBETWEEN(DATE(2024,1,1), DATE(2024,12,31)) -> 45549 | F13: =D13 * VLOOKUP(C13, Product!$A$2:$D$51, 4, FALSE) -> 1950
A14: S43 | B14: E43 | C14: P43 | D14: =RANDBETWEEN(1,3) -> 2 | E14: =RANDBETWEEN(DATE(2024,1,1), DATE(2024,12,31)) -> 45326 | F14: =D14 * VLOOKUP(C14, Product!$A$2:$D$51, 4, FALSE) -> 1132
A15: S6 | B15: E6 | C15: P6 | D15: =RANDBETWEEN(1,3) -> 2 | E15: =RANDBETWEEN(DATE(2024,1,1), DATE(2024,12,31)) -> 45476 | F15: =D15 * VLOOKUP(C15, Product!$A$2:$D$51, 4, FALSE) -> 1220
... A51: S46 | B51: E46 | C51: P46 | D51: =RANDBETWEEN(1,3) -> 3 | E51: =RANDBETWEEN(DATE(2024,1,1), DATE(2024,12,31)) -> 45526 | F51: =D51 * VLOOKUP(C51, Product!$A$2:$D$51, 4, FALSE) -> 1545

Sheet Dashboard
E1: DASHBOARD FOR EMPLOYEE
E2: Total Employees | F2: Average Salary | G2: Maximum Salary | H2: Minimum Salary
E3: =Employee!H3 -> 50 | F3: =Employee!J3 -> 72367.52 | G3: =Employee!L3 -> 99594 | H3: =Employee!K3 -> 40705

Sheet Pivot Table
A8: Department | B8: Sum of Salary
A9: Accounting | B9: 441076
A10: Customer | B10: 706272 | D10: hr department salry
A11: Data Analyst | B11: 197788 | D11: Department | E11: (Multiple Items)
A12: Data Science | B12: 209830
A13: Finance | B13: 404621 | D13: Average of Salary | E13: Count of Department
A14: HR | B14: 399731 | D14: 70341.6 | E14: 20
A15: IT Support | B15: 359457
A16: Marketing | B16: 508208
A17: Sales | B17: 139436
A18: Grand Total | B18: 3366419

Sheet data cleaning
A1: remove duplicates and text->column | F1: before cleaning data | K1: after cleaning data
A2: First Name | B2: Last Name | C2: Phone Number | F2: Name | G2: Email | H2: Location | I2: Amount | K2: Name | L2: Email | M2: Location | N2: Amount
A3: Asha | B3: Reddy | C3: 9876543210 | F3: Asha | G3: asha @gmail.com | H3: Kavali,Nellore, AP | I3: 1000 | K3: Asha | L3: asha@gmail.com | M3: Kavali,Nellore,AP | N3: 1000
A4: Raju | B4: Kumar | C4: 9876543210 | F4: ASHA | G4: asha@gmail.com | H4: Kavali , Nellore , AP | I4: 1000 | K4: Raju | L4: raju@gmail.com | M4: Ongole, AP | N4: 2000
A5: Teja | C5: 9123456789 | F5: Raju | G5: raju@@gmail.com | H5: Ongole , AP | I5: 2000 | K5: Teja | L5: teja@gmail.com | M5: Ongole,AP | N5: 2500
F6: Teja | G6: teja@gmail.com | H6: Ongole-AP | I6: 2500 | K6: Sai Kumar | L6: sai@gmail.com | M6: Nellore ,AP | N6: 3000
F7: sAi kumar | G7: sai @gmail.com | H7: Nellore ,AP | I7: 3000
F8: Raju | G8: raju@gmail.com | H8: Ongole , AP | I8: 2000
K10: trim
K11: =TRIM(K18) | L11: =TRIM(M4) -> Ongole, AP | M11: =TRIM(M3) -> Kavali,Nellore,AP
K13: Proper Name
K14: {=PROPER(K3:K8)} -> Asha
K15: Raju
K16: Teja
K17: Sai Kumar
